[2024-01-07 18:51:29,213] {taskinstance.py:1179} INFO - Dependencies all met for <TaskInstance: Lead_scoring_training_pipeline.training_model manual__2024-01-07T18:50:58.787842+00:00 [queued]>
[2024-01-07 18:51:29,228] {taskinstance.py:1179} INFO - Dependencies all met for <TaskInstance: Lead_scoring_training_pipeline.training_model manual__2024-01-07T18:50:58.787842+00:00 [queued]>
[2024-01-07 18:51:29,229] {taskinstance.py:1376} INFO - 
--------------------------------------------------------------------------------
[2024-01-07 18:51:29,229] {taskinstance.py:1377} INFO - Starting attempt 2 of 2
[2024-01-07 18:51:29,229] {taskinstance.py:1378} INFO - 
--------------------------------------------------------------------------------
[2024-01-07 18:51:29,254] {taskinstance.py:1397} INFO - Executing <Task(PythonOperator): training_model> on 2024-01-07 18:50:58.787842+00:00
[2024-01-07 18:51:29,263] {standard_task_runner.py:52} INFO - Started process 7457 to run task
[2024-01-07 18:51:29,266] {standard_task_runner.py:79} INFO - Running: ['airflow', 'tasks', 'run', 'Lead_scoring_training_pipeline', 'training_model', 'manual__2024-01-07T18:50:58.787842+00:00', '--job-id', '41', '--raw', '--subdir', 'DAGS_FOLDER/lead_scoring_training_pipeline/lead_scoring_training_pipeline.py', '--cfg-path', '/tmp/tmp576knyl9', '--error-file', '/tmp/tmpimhzq88x']
[2024-01-07 18:51:29,267] {standard_task_runner.py:80} INFO - Job 41: Subtask training_model
[2024-01-07 18:51:29,348] {task_command.py:371} INFO - Running <TaskInstance: Lead_scoring_training_pipeline.training_model manual__2024-01-07T18:50:58.787842+00:00 [running]> on host a3830b6d5f93
[2024-01-07 18:51:29,438] {taskinstance.py:1589} INFO - Exporting the following env vars:
AIRFLOW_CTX_DAG_OWNER=airflow
AIRFLOW_CTX_DAG_ID=Lead_scoring_training_pipeline
AIRFLOW_CTX_TASK_ID=training_model
AIRFLOW_CTX_EXECUTION_DATE=2024-01-07T18:50:58.787842+00:00
AIRFLOW_CTX_TRY_NUMBER=2
AIRFLOW_CTX_DAG_RUN_ID=manual__2024-01-07T18:50:58.787842+00:00
[2024-01-07 18:51:29,439] {logging_mixin.py:115} INFO - unable to open database file
[2024-01-07 18:51:29,449] {logging_mixin.py:115} INFO - Loading 'features' table
[2024-01-07 18:51:33,083] {logging_mixin.py:115} INFO - Loading 'target' table
[2024-01-07 18:51:33,326] {utils.py:156} INFO - Creating mlflow experiment
[2024-01-07 18:51:33,533] {logging_mixin.py:115} WARNING - /opt/conda/lib/python3.8/site-packages/sklearn/utils/validation.py:72 DataConversionWarning: A column-vector y was passed when a 1d array was expected. Please change the shape of y to (n_samples, ), for example using ravel().
[2024-01-07 18:51:33,620] {logging_mixin.py:115} INFO - [LightGBM] [Warning] bagging_fraction is set=0.1, subsample=0.1 will be ignored. Current value: bagging_fraction=0.1
[2024-01-07 18:51:33,620] {logging_mixin.py:115} INFO - [LightGBM] [Warning] feature_fraction is set=1.0, colsample_bytree=0.1 will be ignored. Current value: feature_fraction=1.0
[2024-01-07 18:51:41,784] {logging_mixin.py:115} WARNING - Registered model 'LightGBM' already exists. Creating a new version of this model...
[2024-01-07 18:51:41,842] {logging_mixin.py:115} WARNING - 2024/01/07 18:51:41 INFO mlflow.tracking._model_registry.client: Waiting up to 300 seconds for model version to finish creation.                     Model name: LightGBM, version 2
[2024-01-07 18:51:41,842] {logging_mixin.py:115} WARNING - Created version '2' of model 'LightGBM'.
[2024-01-07 18:51:42,028] {taskinstance.py:1909} ERROR - Task failed with exception
Traceback (most recent call last):
  File "/opt/conda/lib/python3.8/site-packages/airflow/operators/python.py", line 171, in execute
    return_value = self.execute_callable()
  File "/opt/conda/lib/python3.8/site-packages/airflow/operators/python.py", line 189, in execute_callable
    return self.python_callable(*self.op_args, **self.op_kwargs)
  File "/home/dags/lead_scoring_training_pipeline/utils.py", line 177, in get_trained_model
    precision = precision_score(y_pred, y_test, average="macro")
NameError: name 'precision_score' is not defined
[2024-01-07 18:51:42,042] {taskinstance.py:1415} INFO - Marking task as FAILED. dag_id=Lead_scoring_training_pipeline, task_id=training_model, execution_date=20240107T185058, start_date=20240107T185129, end_date=20240107T185142
[2024-01-07 18:51:42,067] {standard_task_runner.py:92} ERROR - Failed to execute job 41 for task training_model (name 'precision_score' is not defined; 7457)
[2024-01-07 18:51:42,123] {local_task_job.py:156} INFO - Task exited with return code 1
[2024-01-07 18:51:42,153] {local_task_job.py:273} INFO - 0 downstream tasks scheduled from follow-on schedule check
