[2024-01-07 18:47:59,243] {taskinstance.py:1179} INFO - Dependencies all met for <TaskInstance: Lead_scoring_training_pipeline.training_model manual__2024-01-07T18:47:46.952864+00:00 [queued]>
[2024-01-07 18:47:59,261] {taskinstance.py:1179} INFO - Dependencies all met for <TaskInstance: Lead_scoring_training_pipeline.training_model manual__2024-01-07T18:47:46.952864+00:00 [queued]>
[2024-01-07 18:47:59,261] {taskinstance.py:1376} INFO - 
--------------------------------------------------------------------------------
[2024-01-07 18:47:59,261] {taskinstance.py:1377} INFO - Starting attempt 1 of 2
[2024-01-07 18:47:59,261] {taskinstance.py:1378} INFO - 
--------------------------------------------------------------------------------
[2024-01-07 18:47:59,287] {taskinstance.py:1397} INFO - Executing <Task(PythonOperator): training_model> on 2024-01-07 18:47:46.952864+00:00
[2024-01-07 18:47:59,295] {standard_task_runner.py:52} INFO - Started process 7041 to run task
[2024-01-07 18:47:59,298] {standard_task_runner.py:79} INFO - Running: ['airflow', 'tasks', 'run', 'Lead_scoring_training_pipeline', 'training_model', 'manual__2024-01-07T18:47:46.952864+00:00', '--job-id', '34', '--raw', '--subdir', 'DAGS_FOLDER/lead_scoring_training_pipeline/.ipynb_checkpoints/lead_scoring_training_pipeline-checkpoint.py', '--cfg-path', '/tmp/tmpb77cws9g', '--error-file', '/tmp/tmpnxax4phv']
[2024-01-07 18:47:59,298] {standard_task_runner.py:80} INFO - Job 34: Subtask training_model
[2024-01-07 18:47:59,377] {task_command.py:371} INFO - Running <TaskInstance: Lead_scoring_training_pipeline.training_model manual__2024-01-07T18:47:46.952864+00:00 [running]> on host a3830b6d5f93
[2024-01-07 18:47:59,470] {taskinstance.py:1589} INFO - Exporting the following env vars:
AIRFLOW_CTX_DAG_OWNER=airflow
AIRFLOW_CTX_DAG_ID=Lead_scoring_training_pipeline
AIRFLOW_CTX_TASK_ID=training_model
AIRFLOW_CTX_EXECUTION_DATE=2024-01-07T18:47:46.952864+00:00
AIRFLOW_CTX_TRY_NUMBER=1
AIRFLOW_CTX_DAG_RUN_ID=manual__2024-01-07T18:47:46.952864+00:00
[2024-01-07 18:47:59,471] {logging_mixin.py:115} INFO - unable to open database file
[2024-01-07 18:47:59,482] {logging_mixin.py:115} INFO - Loading 'features' table
[2024-01-07 18:48:03,082] {logging_mixin.py:115} INFO - Loading 'target' table
[2024-01-07 18:48:03,318] {taskinstance.py:1909} ERROR - Task failed with exception
Traceback (most recent call last):
  File "/opt/conda/lib/python3.8/site-packages/airflow/operators/python.py", line 171, in execute
    return_value = self.execute_callable()
  File "/opt/conda/lib/python3.8/site-packages/airflow/operators/python.py", line 189, in execute_callable
    return self.python_callable(*self.op_args, **self.op_kwargs)
  File "/home/dags/lead_scoring_training_pipeline/utils.py", line 146, in get_trained_model
    run_name = EXPERIMENT + "" + date.today().strftime("%d%m_%Y_%H_%M_%S")
NameError: name 'date' is not defined
[2024-01-07 18:48:03,330] {taskinstance.py:1415} INFO - Marking task as UP_FOR_RETRY. dag_id=Lead_scoring_training_pipeline, task_id=training_model, execution_date=20240107T184746, start_date=20240107T184759, end_date=20240107T184803
[2024-01-07 18:48:03,357] {standard_task_runner.py:92} ERROR - Failed to execute job 34 for task training_model (name 'date' is not defined; 7041)
[2024-01-07 18:48:03,404] {local_task_job.py:156} INFO - Task exited with return code 1
[2024-01-07 18:48:03,451] {local_task_job.py:273} INFO - 0 downstream tasks scheduled from follow-on schedule check
